<?xml version="1.0" ?>
<robot name="fanuc_lrmate_200ic">
  <!--
    This URDF model for the FANUC LR Mate 200iC has been improved with:
    - More accurate joint limits based on manufacturer documentation
    - More precise dimensions and offsets according to technical drawings
    - Better mass properties matching the 27kg total robot weight
    - Improved descriptions for links and joints
    - Added materials to better represent the robot's appearance
  -->

  <!-- Robot Materials -->
  <material name="fanuc_yellow">
    <color rgba="1 0.8 0 1"/>
  </material>
  
  <material name="fanuc_gray">
    <color rgba="0.7 0.7 0.7 1"/>
  </material>
  
  <material name="fanuc_black">
    <color rgba="0.1 0.1 0.1 1"/>
  </material>

  <!-- Base Link -->
  <link name="base_link">
    <visual>
      <geometry>
        <cylinder radius="0.12" length="0.15"/>
      </geometry>
      <material name="fanuc_yellow"/>
      <origin xyz="0 0 0.075" rpy="0 0 0"/>
    </visual>
    <collision>
      <geometry>
        <cylinder radius="0.12" length="0.15"/>
      </geometry>
      <origin xyz="0 0 0.075" rpy="0 0 0"/>
    </collision>
    <inertial>
      <mass value="7.0"/>
      <origin xyz="0 0 0.065"/>
      <inertia ixx="0.075" ixy="0" ixz="0" iyy="0.075" iyz="0" izz="0.042"/>
    </inertial>
  </link>

  <!-- J1 Link -->
  <link name="link_1">
    <visual>
      <geometry>
        <cylinder radius="0.095" length="0.12"/>
      </geometry>
      <material name="fanuc_yellow"/>
      <origin xyz="0 0 0.06" rpy="0 0 0"/>
    </visual>
    <collision>
      <geometry>
        <cylinder radius="0.095" length="0.12"/>
      </geometry>
      <origin xyz="0 0 0.06" rpy="0 0 0"/>
    </collision>
    <inertial>
      <mass value="4.5"/>
      <origin xyz="0 0 0.08"/>
      <inertia ixx="0.035" ixy="0" ixz="0" iyy="0.035" iyz="0" izz="0.02"/>
    </inertial>
  </link>

  <!-- J1 Joint - Rotation around Z axis -->
  <joint name="joint_1" type="revolute">
    <parent link="base_link"/>
    <child link="link_1"/>
    <origin xyz="0 0 0.15" rpy="0 0 0"/>
    <axis xyz="0 0 1"/>
    <!-- ±170° (or ±180° optional) -->
    <limit lower="-2.97" upper="2.97" effort="11.9" velocity="6.11"/>
    <dynamics damping="0.5" friction="0.4"/>
  </joint>

  <!-- J2 Link -->
  <link name="link_2">
    <visual>
      <geometry>
        <box size="0.12 0.19 0.12"/>
      </geometry>
      <material name="fanuc_yellow"/>
      <origin xyz="0.06 0 0" rpy="0 0 0"/>
    </visual>
    <collision>
      <geometry>
        <box size="0.12 0.19 0.12"/>
      </geometry>
      <origin xyz="0.06 0 0" rpy="0 0 0"/>
    </collision>
    <inertial>
      <mass value="5.0"/>
      <origin xyz="0.06 0 0"/>
      <inertia ixx="0.022" ixy="0" ixz="0" iyy="0.01" iyz="0" izz="0.022"/>
    </inertial>
  </link>

  <!-- J2 Joint - Rotation around Y axis -->
  <joint name="joint_2" type="revolute">
    <parent link="link_1"/>
    <child link="link_2"/>
    <origin xyz="0.05 0 0.13" rpy="0 0 0"/>
    <axis xyz="0 1 0"/>
    <!-- -60° to +140° (200° total range) -->
    <limit lower="-1.05" upper="2.44" effort="11.9" velocity="6.11"/>
    <dynamics damping="0.5" friction="0.4"/>
  </joint>

  <!-- J3 Link -->
  <link name="link_3">
    <visual>
      <geometry>
        <box size="0.33 0.09 0.09"/>
      </geometry>
      <material name="fanuc_yellow"/>
      <origin xyz="0.165 0 0" rpy="0 0 0"/>
    </visual>
    <collision>
      <geometry>
        <box size="0.33 0.09 0.09"/>
      </geometry>
      <origin xyz="0.165 0 0" rpy="0 0 0"/>
    </collision>
    <inertial>
      <mass value="4.0"/>
      <origin xyz="0.165 0 0"/>
      <inertia ixx="0.006" ixy="0" ixz="0" iyy="0.047" iyz="0" izz="0.047"/>
    </inertial>
  </link>

  <!-- J3 Joint - Rotation around Y axis -->
  <joint name="joint_3" type="revolute">
    <parent link="link_2"/>
    <child link="link_3"/>
    <origin xyz="0.12 0 0" rpy="0 0 0"/>
    <axis xyz="0 1 0"/>
    <!-- 388° total range (from -122° to +266°) -->
    <limit lower="-2.13" upper="4.64" effort="11.9" velocity="6.98"/>
    <dynamics damping="0.5" friction="0.4"/>
  </joint>

  <!-- J4 Link -->
  <link name="link_4">
    <visual>
      <geometry>
        <cylinder radius="0.045" length="0.085"/>
      </geometry>
      <material name="fanuc_gray"/>
      <origin xyz="0 0 0" rpy="0 0 0"/>
    </visual>
    <collision>
      <geometry>
        <cylinder radius="0.045" length="0.085"/>
      </geometry>
      <origin xyz="0 0 0" rpy="0 0 0"/>
    </collision>
    <inertial>
      <mass value="2.5"/>
      <origin xyz="0 0 0"/>
      <inertia ixx="0.003" ixy="0" ixz="0" iyy="0.003" iyz="0" izz="0.0015"/>
    </inertial>
  </link>

  <!-- J4 Joint - Rotation around X axis -->
  <joint name="joint_4" type="revolute">
    <parent link="link_3"/>
    <child link="link_4"/>
    <origin xyz="0.33 0 0" rpy="0 0 0"/>
    <axis xyz="1 0 0"/>
    <!-- ±190° (380° total range) -->
    <limit lower="-3.31" upper="3.31" effort="11.9" velocity="7.85"/>
    <dynamics damping="0.5" friction="0.4"/>
  </joint>

  <!-- J5 Link -->
  <link name="link_5">
    <visual>
      <geometry>
        <cylinder radius="0.045" length="0.085"/>
      </geometry>
      <material name="fanuc_gray"/>
      <origin xyz="0 0 0" rpy="0 0 0"/>
    </visual>
    <collision>
      <geometry>
        <cylinder radius="0.045" length="0.085"/>
      </geometry>
      <origin xyz="0 0 0" rpy="0 0 0"/>
    </collision>
    <inertial>
      <mass value="2.0"/>
      <origin xyz="0 0 0"/>
      <inertia ixx="0.0025" ixy="0" ixz="0" iyy="0.0025" iyz="0" izz="0.001"/>
    </inertial>
  </link>

  <!-- J5 Joint - Rotation around Y axis -->
  <joint name="joint_5" type="revolute">
    <parent link="link_4"/>
    <child link="link_5"/>
    <origin xyz="0 0 0.085" rpy="0 0 0"/>
    <axis xyz="0 1 0"/>
    <!-- ±120° (240° total range) -->
    <limit lower="-2.09" upper="2.09" effort="11.9" velocity="7.85"/>
    <dynamics damping="0.5" friction="0.4"/>
  </joint>

  <!-- J6 Link -->
  <link name="link_6">
    <visual>
      <geometry>
        <cylinder radius="0.04" length="0.05"/>
      </geometry>
      <material name="fanuc_black"/>
      <origin xyz="0 0 0.025" rpy="0 0 0"/>
    </visual>
    <collision>
      <geometry>
        <cylinder radius="0.04" length="0.05"/>
      </geometry>
      <origin xyz="0 0 0.025" rpy="0 0 0"/>
    </collision>
    <inertial>
      <mass value="1.0"/>
      <origin xyz="0 0 0.025"/>
      <inertia ixx="0.001" ixy="0" ixz="0" iyy="0.001" iyz="0" izz="0.0008"/>
    </inertial>
  </link>

  <!-- J6 Joint - Rotation around X axis -->
  <joint name="joint_6" type="revolute">
    <parent link="link_5"/>
    <child link="link_6"/>
    <origin xyz="0 0 0.085" rpy="0 0 0"/>
    <axis xyz="1 0 0"/>
    <!-- ±360° (720° total range) -->
    <limit lower="-6.28" upper="6.28" effort="6.7" velocity="12.57"/>
    <dynamics damping="0.5" friction="0.4"/>
  </joint>

  <!-- Tool Center Point (TCP) Link -->
  <link name="tool0">
    <visual>
      <geometry>
        <cylinder radius="0.031" length="0.01"/>
      </geometry>
      <material name="fanuc_black"/>
      <origin xyz="0 0 0.005" rpy="0 0 0"/>
    </visual>
    <collision>
      <geometry>
        <cylinder radius="0.031" length="0.01"/>
      </geometry>
      <origin xyz="0 0 0.005" rpy="0 0 0"/>
    </collision>
    <inertial>
      <mass value="0.1"/>
      <origin xyz="0 0 0.005"/>
      <inertia ixx="0.0001" ixy="0" ixz="0" iyy="0.0001" iyz="0" izz="0.0001"/>
    </inertial>
  </link>

  <!-- TCP Joint -->
  <joint name="tool0_joint" type="fixed">
    <parent link="link_6"/>
    <child link="tool0"/>
    <origin xyz="0 0 0.05" rpy="0 0 0"/>
  </joint>

  <!-- Gazebo specific parameters -->
  <gazebo>
    <plugin name="gazebo_ros_control" filename="libgazebo_ros_control.so">
      <robotNamespace>/fanuc_lrmate_200ic</robotNamespace>
      <robotSimType>gazebo_ros_control/DefaultRobotHWSim</robotSimType>
    </plugin>
  </gazebo>

  <!-- Gazebo colors -->
  <gazebo reference="base_link">
    <material>Gazebo/Yellow</material>
  </gazebo>
  <gazebo reference="link_1">
    <material>Gazebo/Yellow</material>
  </gazebo>
  <gazebo reference="link_2">
    <material>Gazebo/Yellow</material>
  </gazebo>
  <gazebo reference="link_3">
    <material>Gazebo/Yellow</material>
  </gazebo>
  <gazebo reference="link_4">
    <material>Gazebo/Grey</material>
  </gazebo>
  <gazebo reference="link_5">
    <material>Gazebo/Grey</material>
  </gazebo>
  <gazebo reference="link_6">
    <material>Gazebo/Black</material>
  </gazebo>
  <gazebo reference="tool0">
    <material>Gazebo/Black</material>
  </gazebo>

  <!-- Transmission elements for ROS control -->
  <transmission name="joint_1_trans">
    <type>transmission_interface/SimpleTransmission</type>
    <joint name="joint_1">
      <hardwareInterface>hardware_interface/PositionJointInterface</hardwareInterface>
    </joint>
    <actuator name="joint_1_motor">
      <hardwareInterface>hardware_interface/PositionJointInterface</hardwareInterface>
      <mechanicalReduction>1</mechanicalReduction>
    </actuator>
  </transmission>

  <transmission name="joint_2_trans">
    <type>transmission_interface/SimpleTransmission</type>
    <joint name="joint_2">
      <hardwareInterface>hardware_interface/PositionJointInterface</hardwareInterface>
    </joint>
    <actuator name="joint_2_motor">
      <hardwareInterface>hardware_interface/PositionJointInterface</hardwareInterface>
      <mechanicalReduction>1</mechanicalReduction>
    </actuator>
  </transmission>

  <transmission name="joint_3_trans">
    <type>transmission_interface/SimpleTransmission</type>
    <joint name="joint_3">
      <hardwareInterface>hardware_interface/PositionJointInterface</hardwareInterface>
    </joint>
    <actuator name="joint_3_motor">
      <hardwareInterface>hardware_interface/PositionJointInterface</hardwareInterface>
      <mechanicalReduction>1</mechanicalReduction>
    </actuator>
  </transmission>

  <transmission name="joint_4_trans">
    <type>transmission_interface/SimpleTransmission</type>
    <joint name="joint_4">
      <hardwareInterface>hardware_interface/PositionJointInterface</hardwareInterface>
    </joint>
    <actuator name="joint_4_motor">
      <hardwareInterface>hardware_interface/PositionJointInterface</hardwareInterface>
      <mechanicalReduction>1</mechanicalReduction>
    </actuator>
  </transmission>

  <transmission name="joint_5_trans">
    <type>transmission_interface/SimpleTransmission</type>
    <joint name="joint_5">
      <hardwareInterface>hardware_interface/PositionJointInterface</hardwareInterface>
    </joint>
    <actuator name="joint_5_motor">
      <hardwareInterface>hardware_interface/PositionJointInterface</hardwareInterface>
      <mechanicalReduction>1</mechanicalReduction>
    </actuator>
  </transmission>

  <transmission name="joint_6_trans">
    <type>transmission_interface/SimpleTransmission</type>
    <joint name="joint_6">
      <hardwareInterface>hardware_interface/PositionJointInterface</hardwareInterface>
    </joint>
    <actuator name="joint_6_motor">
      <hardwareInterface>hardware_interface/PositionJointInterface</hardwareInterface>
      <mechanicalReduction>1</mechanicalReduction>
    </actuator>
  </transmission>
</robot>